#VRML_SIM R2025a utf8
# license: Apache License 2.0
# license url: http://www.apache.org/licenses/LICENSE-2.0
# This is a proto file for Webots for the RoboCayote
# Extracted from: C:\Users\bogda\OneDrive\Documents\Senior_Design_Project\robo_cayote_des.urdf

# THIS CODE IS GENERATED BY GOOGLE GEMINI --> CHECKED BY ME, BUT IT CAN STILL HAVE ISSUES. SUPPOSEDLY IS THE SAME AS WHAT DAVID'S URDF FILE LOOKS LIKE

PROTO RoboCayote [
  field  SFVec3f     translation     0 0 0
  field  SFRotation  rotation        0 0 1 0
  field  SFString    name            "RoboCayote"  # Is `Robot.name`.
  field  SFString    controller      "void"        # Is `Robot.controller`.
  field  MFString    controllerArgs  []            # Is `Robot.controllerArgs`.
  field  SFString    customData      ""            # Is `Robot.customData`.
  field  SFBool      supervisor      FALSE         # Is `Robot.supervisor`.
  field  SFBool      synchronization TRUE          # Is `Robot.synchronization`.
  field  SFBool      selfCollision   FALSE         # Is `Robot.selfCollision`.
]
{
  Robot {
    translation IS translation
    rotation IS rotation
    controller IS controller
    controllerArgs IS controllerArgs
    customData IS customData
    supervisor IS supervisor
    synchronization IS synchronization
    selfCollision IS selfCollision
    children [
      Pose {
        translation 0.000000 0.140000 0.000000
        children [
          Shape {
            appearance PBRAppearance {
              baseColor 0.500000 0.500000 0.500000
              roughness 1.000000
              metalness 0
            }
            geometry Box {
               size 0.840000 0.060000 0.435900
            }
          }
        ]
      }
      SliderJoint {
        jointParameters JointParameters {
          axis 0.000000 1.000000 0.000000
        }
        device [
          LinearMotor {
            name "slider_fr"
            maxVelocity 10.0
            minPosition -0.1
            maxPosition 0.1
            maxForce 10.0
          }
          PositionSensor {
            name "slider_fr_sensor"
          }
        ]
        endPoint Solid {
          translation 0.310000 0.020000 -0.280000
          children [
            Shape {
              appearance PBRAppearance {
                baseColor 0.500000 0.500000 0.500000
                roughness 1.000000
                metalness 0
              }
              geometry Box {
                 size 0.001000 0.001000 0.001000
              }
            }
            HingeJoint {
              jointParameters HingeJointParameters {
                axis 0.000000 1.000000 0.000000
              }
              device [
                RotationalMotor {
                  name "steer_motor_fr"
                  maxTorque 10000
                }
                PositionSensor {
                  name "steer_motor_fr_sensor"
                }
              ]
              endPoint Solid {
                children [
                  Shape {
                    appearance PBRAppearance {
                      baseColor 0.500000 0.500000 0.500000
                      roughness 1.000000
                      metalness 0
                    }
                    geometry Box {
                       size 0.001000 0.001000 0.001000
                    }
                  }
                  HingeJoint {
                    jointParameters HingeJointParameters {
                      axis 0.000000 0.000000 1.000000
                    }
                    device [
                      RotationalMotor {
                        name "wheel_motor_fr"
                        maxTorque 10000
                      }
                      PositionSensor {
                        name "wheel_motor_fr_sensor"
                      }
                    ]
                    endPoint Solid {
                      children [
                        Shape {
                          appearance PBRAppearance {
                            baseColor 0.500000 0.500000 0.500000
                            roughness 1.000000
                            metalness 0
                          }
                          geometry Cylinder {
                            radius 0.06
                            height 0.05
                          }
                        }
                      ]
                      name "solid_1"
                      boundingObject Cylinder {
                        radius 0.06
                        height 0.05
                      }
                      physics Physics {
                        density -1
                        mass 0.500000
                        centerOfMass [ 0.000000 0.000000 0.000000 ]
                        inertiaMatrix [
                          1.000000e-03 1.000000e-03 1.000000e-03
                          0.000000e+00 0.000000e+00 0.000000e+00
                        ]
                      }
                    }
                  }
                ]
                name "solid_0"
                physics Physics {
                  density -1
                  mass 0.010000
                  centerOfMass [ 0.000000 0.000000 0.000000 ]
                  inertiaMatrix [
                    1.000000e-04 1.000000e-04 1.000000e-04
                    0.000000e+00 0.000000e+00 0.000000e+00
                  ]
                }
              }
            }
          ]
          name "solid"
          physics Physics {
            density -1
            mass 0.010000
            centerOfMass [ 0.000000 0.000000 0.000000 ]
            inertiaMatrix [
              1.000000e-04 1.000000e-04 1.000000e-04
              0.000000e+00 0.000000e+00 0.000000e+00
            ]
          }
        }
      }
      SliderJoint {
        jointParameters JointParameters {
          axis 0.000000 1.000000 0.000000
        }
        device [
          LinearMotor {
            name "slider_fl"
            maxVelocity 10.0
            minPosition -0.1
            maxPosition 0.1
            maxForce 10.0
          }
          PositionSensor {
            name "slider_fl_sensor"
          }
        ]
        endPoint Solid {
          translation 0.310000 0.020000 0.280000
          children [
            Shape {
              appearance PBRAppearance {
                baseColor 0.500000 0.500000 0.500000
                roughness 1.000000
                metalness 0
              }
              geometry Box {
                 size 0.001000 0.001000 0.001000
              }
            }
            HingeJoint {
              jointParameters HingeJointParameters {
                axis 0.000000 1.000000 0.000000
              }
              device [
                RotationalMotor {
                  name "steer_motor_fl"
                  maxTorque 10000
                }
                PositionSensor {
                  name "steer_motor_fl_sensor"
                }
              ]
              endPoint Solid {
                children [
                  Shape {
                    appearance PBRAppearance {
                      baseColor 0.500000 0.500000 0.500000
                      roughness 1.000000
                      metalness 0
                    }
                    geometry Box {
                       size 0.001000 0.001000 0.001000
                    }
                  }
                  HingeJoint {
                    jointParameters HingeJointParameters {
                      axis 0.000000 0.000000 1.000000
                    }
                    device [
                      RotationalMotor {
                        name "wheel_motor_fl"
                        maxTorque 10000
                      }
                      PositionSensor {
                        name "wheel_motor_fl_sensor"
                      }
                    ]
                    endPoint Solid {
                      children [
                        Shape {
                          appearance PBRAppearance {
                            baseColor 0.500000 0.500000 0.500000
                            roughness 1.000000
                            metalness 0
                          }
                          geometry Cylinder {
                            radius 0.06
                            height 0.05
                          }
                        }
                      ]
                      name "solid_5"
                      boundingObject Cylinder {
                        radius 0.06
                        height 0.05
                      }
                      physics Physics {
                        density -1
                        mass 0.500000
                        centerOfMass [ 0.000000 0.000000 0.000000 ]
                        inertiaMatrix [
                          1.000000e-03 1.000000e-03 1.000000e-03
                          0.000000e+00 0.000000e+00 0.000000e+00
                        ]
                      }
                    }
                  }
                ]
                name "solid_4"
                physics Physics {
                  density -1
                  mass 0.010000
                  centerOfMass [ 0.000000 0.000000 0.000000 ]
                  inertiaMatrix [
                    1.000000e-04 1.000000e-04 1.000000e-04
                    0.000000e+00 0.000000e+00 0.000000e+00
                  ]
                }
              }
            }
          ]
          name "solid_3"
          physics Physics {
            density -1
            mass 0.010000
            centerOfMass [ 0.000000 0.000000 0.000000 ]
            inertiaMatrix [
              1.000000e-04 1.000000e-04 1.000000e-04
              0.000000e+00 0.000000e+00 0.000000e+00
            ]
          }
        }
      }
      Solid {
        children [
          Shape {
            appearance PBRAppearance {
              baseColor 0.500000 0.500000 0.500000
              roughness 1.000000
              metalness 0
            }
            geometry Box {
               size 0.001000 0.001000 0.001000
            }
          }
        ]
        name "gps"
        physics Physics {
          density -1
          mass 0.010000
          centerOfMass [ 0.000000 0.000000 0.000000 ]
          inertiaMatrix [
            1.000000e-04 1.000000e-04 1.000000e-04
            0.000000e+00 0.000000e+00 0.000000e+00
          ]
        }
      }
      Solid {
        children [
          Shape {
            appearance PBRAppearance {
              baseColor 0.500000 0.500000 0.500000
              roughness 1.000000
              metalness 0
            }
            geometry Box {
               size 0.001000 0.001000 0.001000
            }
          }
        ]
        name "imu"
        physics Physics {
          density -1
          mass 0.010000
          centerOfMass [ 0.000000 0.000000 0.000000 ]
          inertiaMatrix [
            1.000000e-04 1.000000e-04 1.000000e-04
            0.000000e+00 0.000000e+00 0.000000e+00
          ]
        }
      }
    ]
    name IS name
    boundingObject Pose {
      translation 0.000000 0.140000 0.000000
      children [
        Box {
           size 0.840000 0.060000 0.435900
        }
      ]
    }
    physics Physics {
      density -1
      mass 5.000000
      centerOfMass [ 0.000000 0.000000 0.000000 ]
      inertiaMatrix [
        1.000000e-01 1.000000e-01 1.000000e-01
        0.000000e+00 0.000000e+00 0.000000e+00
      ]
    }
  }
}
