#VRML_SIM R2025a utf8
# license: Apache License 2.0
# license url: http://www.apache.org/licenses/LICENSE-2.0
# This is a proto file for Webots for the RoboCayote
# Extracted from: C:\Users\bogda\OneDrive\Documents\Senior_Design_Project\robo_cayote_des.urdf

PROTO RoboCayote [
  field  SFVec3f     translation     0 0 0
  field  SFRotation  rotation        0 0 1 0
  field  SFString    name            "RoboCayote"  # Is `Robot.name`.
  field  SFString    controller      "void"        # Is `Robot.controller`.
  field  MFString    controllerArgs  []            # Is `Robot.controllerArgs`.
  field  SFString    customData      ""            # Is `Robot.customData`.
  field  SFBool      supervisor      FALSE         # Is `Robot.supervisor`.
  field  SFBool      synchronization TRUE          # Is `Robot.synchronization`.
  field  SFBool      selfCollision   FALSE         # Is `Robot.selfCollision`.
  field  SFBool      staticBase      TRUE          # Defines if the robot base should be pinned to the static environment.
]
{
  Robot {
    translation IS translation
    rotation IS rotation
    controller IS controller
    controllerArgs IS controllerArgs
    customData IS customData
    supervisor IS supervisor
    synchronization IS synchronization
    selfCollision IS selfCollision
    children [
      Pose {
        translation 0.000000 0.140000 0.000000
        children [
          Shape {
            appearance PBRAppearance {
              baseColor 0.500000 0.500000 0.500000
              roughness 1.000000
              metalness 0
            }
            geometry Box {
               size 0.840000 0.060000 0.435900
            }
          }
        ]
      }
      SliderJoint {
        jointParameters JointParameters {
          axis 0.000000 1.000000 0.000000
        }
        device [
          LinearMotor {
            name "base_link-solid_1"
            maxVelocity 10.0
            minPosition -0.1
            maxPosition 0.1
            maxForce 10.0
          }
          PositionSensor {
            name "base_link-solid_1_sensor"
          }
        ]
        endPoint Solid {
          translation 0.310000 0.020000 -0.280000
          children [
            Shape {
              appearance PBRAppearance {
                baseColor 0.500000 0.500000 0.500000
                roughness 1.000000
                metalness 0
              }
              geometry Cylinder {
                radius 0.06
                height 0.05
              }
            }
          ]
          name "solid_1"
          boundingObject Cylinder {
            radius 0.06
            height 0.05
          }
          physics Physics {
          }
        }
      }
      SliderJoint {
        jointParameters JointParameters {
          axis 0.000000 1.000000 0.000000
        }
        device [
          LinearMotor {
            name "base_link-solid_5"
            maxVelocity 10.0
            minPosition -0.1
            maxPosition 0.1
            maxForce 10.0
          }
          PositionSensor {
            name "base_link-solid_5_sensor"
          }
        ]
        endPoint Solid {
          translation 0.310000 0.020000 0.280000
          children [
            Shape {
              appearance PBRAppearance {
                baseColor 0.500000 0.500000 0.500000
                roughness 1.000000
                metalness 0
              }
              geometry Cylinder {
                radius 0.06
                height 0.05
              }
            }
          ]
          name "solid_5"
          boundingObject Cylinder {
            radius 0.06
            height 0.05
          }
          physics Physics {
          }
        }
      }
      SliderJoint {
        jointParameters JointParameters {
          axis 0.000000 1.000000 0.000000
        }
        device [
          LinearMotor {
            name "base_link-solid_9"
            maxVelocity 10.0
            minPosition -0.1
            maxPosition 0.1
            maxForce 10.0
          }
          PositionSensor {
            name "base_link-solid_9_sensor"
          }
        ]
        endPoint Solid {
          translation -0.310000 0.020000 -0.280000
          children [
            Shape {
              appearance PBRAppearance {
                baseColor 0.500000 0.500000 0.500000
                roughness 1.000000
                metalness 0
              }
              geometry Cylinder {
                radius 0.06
                height 0.05
              }
            }
          ]
          name "solid_9"
          boundingObject Cylinder {
            radius 0.06
            height 0.05
          }
          physics Physics {
          }
        }
      }
      SliderJoint {
        jointParameters JointParameters {
          axis 0.000000 1.000000 0.000000
        }
        device [
          LinearMotor {
            name "base_link-solid_13"
            maxVelocity 10.0
            minPosition -0.1
            maxPosition 0.1
            maxForce 10.0
          }
          PositionSensor {
            name "base_link-solid_13_sensor"
          }
        ]
        endPoint Solid {
          translation -0.310000 0.020000 0.280000
          children [
            Shape {
              appearance PBRAppearance {
                baseColor 0.500000 0.500000 0.500000
                roughness 1.000000
                metalness 0
              }
              geometry Cylinder {
                radius 0.06
                height 0.05
              }
            }
          ]
          name "solid_13"
          boundingObject Cylinder {
            radius 0.06
            height 0.05
          }
          physics Physics {
          }
        }
      }
    ]
    name IS name
    boundingObject Pose {
      translation 0.000000 0.140000 0.000000
      children [
        Box {
           size 0.840000 0.060000 0.435900
        }
      ]
    }
  }
}
